Workbook

Sheet Glossary
A1: Trade Balance | B1: Exports minus Imports
A2: Basic Balance | B2: Trade Balance plus Net Long-Term Capital Flows
A3: Equation for Assignment: ln(TWI(t)) = 0.000871*Basic Balance(t-T) + 4.54
A4: TWI is the Trade Weighted Dollar Index

Sheet TIC data
A1: FOREIGN | B1: PURCHASES | C1: AND SALES | D1: OF LONG-T | E1: ERM DOMES | F1: TIC AND | G1: FOREIGN S | H1: ECURITIES | J1: BY TYPE
A2: Data | B2: column ti | C2: tles corre | D2: spond to c | E2: olumn tit | F2: les in T | G2: reasury B | H2: ulletin T | J2: able CM-V | K2: -4, exclu | L2: ding CM-V | M2: -4 column | N2: s (1) and | O2: (8).
A3: Refer | B3: to CNTRY | C3: CDS.TXT fi | D3: le for "Cn | E3: try Code" | F3: identif | G3: ication.
A4: All a | B4: mounts in | C4: millions | D4: of dollars | E4: .
C6: <------- | D6: =----Gross -> #NAME? | E6: Purchases | F6: by Fore | G6: igners--- | H6: --------> | J6: <------- | K6: =------Gro -> #NAME? | L6: ss Sales | M6: by Foreig | N6: ners----- | O6: -------->
C7: <------- | D7: =---------f -> #NAME? | E7: rom U.S. | F7: Resident | G7: s-------- | H7: --------> | J7: <------- | K7: --------- | L7: =-to U.S. -> #NAME? | M7: Residents | N7: --------- | O7: -------->
C8: U.S. | D8: U.S. | J8: U.S. | K8: U.S.
C9: Treasury | D9: Gov't | E9: U.S. | F9: U.S. | J9: Treasury | K9: Gov't | L9: U.S. | M9: U.S.
A10: Cntry | C10: Bonds & | D10: Agency | E10: Corp. | F10: Corp. | G10: Foreign | H10: Foreign | J10: Bonds & | K10: Agency | L10: Corp. | M10: Corp. | N10: Foreign | O10: Foreign
A11: Code | B11: Year-Mo | C11: Notes | D11: Bonds | E11: Bonds | F11: Stocks | G11: Bonds | H11: Stocks | J11: Notes | K11: Bonds | L11: Bonds | M11: Stocks | N11: Bonds | O11: Stocks | Q11: Net | R11: Net | S11: Net | T11: Net | V11: Net | W11: Net | Y11: Net | Z11: Net | AA11: Net | AD11: 12 m Net | AE11: 12 m Net | AF11: 12 m Net | AI11: 12 m Net | AJ11: 12 m Net | AK11: 12 m Net | AL11: 12 m Net | AM11: 12M Net non
A12: ----- | B12: ------- | C12: -------- | D12: -------- | E12: -------- | F12: -------- | G12: -------- | H12: -------- | J12: -------- | K12: -------- | L12: -------- | M12: -------- | N12: -------- | O12: -------- | Q12: Treasury | R12: Agency | S12: Corp | T12: For bonds | V12: US stks | W12: For Stks | Y12: Bond | Z12: stk | AA12: Net flows | AD12: Bond | AE12: stk | AF12: Net flows | AI12: Treasury | AJ12: Agency | AK12: Corp | AL12: For bonds | AM12: Treasury Flows
A13: 99996 | B13: 1977-01 | C13: 1632 | D13: 132 | E13: 258 | F13: 1430 | G13: 776 | H13: 179 | J13: 1122 | K13: 44 | L13: 263 | M13: 1131 | N13: 858 | O13: 198 | Q13: =(C13-J13)/1000 -> 0.51 | R13: =(D13-K13)/1000 -> 0.088 | S13: =(E13-L13)/1000 -> -0.005 | T13: =(G13-N13)/1000 -> -0.082 | V13: =(F13-M13)/1000 -> 0.299 | W13: =(H13-O13)/1000 -> -0.019 | Y13: =SUM(Q13:T13) -> 0.511 | Z13: =V13+W13 -> 0.28 | AA13: =SUM(Q13:W13) -> 0.791
A14: 99996 | B14: 1977-02 | C14: 2673 | D14: 69 | E14: 476 | F14: 1167 | G14: 555 | H14: 129 | J14: 1377 | K14: 64 | L14: 164 | M14: 1032 | N14: 941 | O14: 237 | Q14: =(C14-J14)/1000 -> 1.296 | R14: =(D14-K14)/1000 -> 0.005 | S14: =(E14-L14)/1000 -> 0.312 | T14: =(G14-N14)/1000 -> -0.386 | V14: =(F14-M14)/1000 -> 0.135 | W14: =(H14-O14)/1000 -> -0.108 | Y14: =SUM(Q14:T14) -> 1.227 | Z14: =V14+W14 -> 0.027 | AA14: =SUM(Q14:W14) -> 1.254
A15: 99996 | B15: 1977-03 | C15: 3064 | D15: 156 | E15: 190 | F15: 1105 | G15: 573 | H15: 182 | J15: 1559 | K15: 80 | L15: 144 | M15: 976 | N15: 660 | O15: 249 | Q15: =(C15-J15)/1000 -> 1.505 | R15: =(D15-K15)/1000 -> 0.076 | S15: =(E15-L15)/1000 -> 0.046 | T15: =(G15-N15)/1000 -> -0.087 | V15: =(F15-M15)/1000 -> 0.129 | W15: =(H15-O15)/1000 -> -0.067 | Y15: =SUM(Q15:T15) -> 1.54 | Z15: =V15+W15 -> 0.062 | AA15: =SUM(Q15:W15) -> 1.602
A16: 99996 | B16: 1977-04 | C16: 2739 | D16: 427 | E16: 451 | F16: 1142 | G16: 510 | H16: 153 | J16: 1794 | K16: 107 | L16: 137 | M16: 906 | N16: 578 | O16: 197 | Q16: =(C16-J16)/1000 -> 0.945 | R16: =(D16-K16)/1000 -> 0.32 | S16: =(E16-L16)/1000 -> 0.314 | T16: =(G16-N16)/1000 -> -0.068 | V16: =(F16-M16)/1000 -> 0.236 | W16: =(H16-O16)/1000 -> -0.044 | Y16: =SUM(Q16:T16) -> 1.511 | Z16: =V16+W16 -> 0.192 | AA16: =SUM(Q16:W16) -> 1.703
A17: 99996 | B17: 1977-05 | C17: 1986 | D17: 281 | E17: 332 | F17: 1210 | G17: 561 | H17: 198 | J17: 1098 | K17: 162 | L17: 140 | M17: 978 | N17: 1426 | O17: 211 | Q17: =(C17-J17)/1000 -> 0.888 | R17: =(D17-K17)/1000 -> 0.119 | S17: =(E17-L17)/1000 -> 0.192 | T17: =(G17-N17)/1000 -> -0.865 | V17: =(F17-M17)/1000 -> 0.232 | W17: =(H17-O17)/1000 -> -0.013 | Y17: =SUM(Q17:T17) -> 0.334 | Z17: =V17+W17 -> 0.219 | AA17: =SUM(Q17:W17) -> 0.553
A18: 99996 | B18: 1977-06 | C18: 3253 | D18: 709 | E18: 324 | F18: 1202 | G18: 594 | H18: 167 | J18: 927 | K18: 244 | L18: 191 | M18: 950 | N18: 1372 | O18: 228 | Q18: =(C18-J18)/1000 -> 2.326 | R18: =(D18-K18)/1000 -> 0.465 | S18: =(E18-L18)/1000 -> 0.133 | T18: =(G18-N18)/1000 -> -0.778 | V18: =(F18-M18)/1000 -> 0.252 | W18: =(H18-O18)/1000 -> -0.061 | Y18: =SUM(Q18:T18) -> 2.146 | Z18: =V18+W18 -> 0.191 | AA18: =SUM(Q18:W18) -> 2.337
A19: 99996 | B19: 1977-07 | C19: 1643 | D19: 439 | E19: 465 | F19: 1373 | G19: 729 | H19: 157 | J19: 436 | K19: 134 | L19: 150 | M19: 1163 | N19: 933 | O19: 422 | Q19: =(C19-J19)/1000 -> 1.207 | R19: =(D19-K19)/1000 -> 0.305 | S19: =(E19-L19)/1000 -> 0.315 | T19: =(G19-N19)/1000 -> -0.204 | V19: =(F19-M19)/1000 -> 0.21 | W19: =(H19-O19)/1000 -> -0.265 | Y19: =SUM(Q19:T19) -> 1.623 | Z19: =V19+W19 -> -0.055 | AA19: =SUM(Q19:W19) -> 1.568
A20: 99996 | B20: 1977-08 | C20: 4988 | D20: 388 | E20: 315 | F20: 1023 | G20: 799 | H20: 169 | J20: 992 | K20: 51 | L20: 235 | M20: 900 | N20: 1821 | O20: 232 | Q20: =(C20-J20)/1000 -> 3.996 | R20: =(D20-K20)/1000 -> 0.337 | S20: =(E20-L20)/1000 -> 0.08 | T20: =(G20-N20)/1000 -> -1.022 | V20: =(F20-M20)/1000 -> 0.123 | W20: =(H20-O20)/1000 -> -0.063 | Y20: =SUM(Q20:T20) -> 3.391 | Z20: =V20+W20 -> 0.06 | AA20: =SUM(Q20:W20) -> 3.451
A21: 99996 | B21: 1977-09 | C21: 4548 | D21: 280 | E21: 233 | F21: 1012 | G21: 681 | H21: 168 | J21: 1112 | K21: 270 | L21: 194 | M21: 847 | N21: 1335 | O21: 138 | Q21: =(C21-J21)/1000 -> 3.436 | R21: =(D21-K21)/1000 -> 0.01 | S21: =(E21-L21)/1000 -> 0.039 | T21: =(G21-N21)/1000 -> -0.654 | V21: =(F21-M21)/1000 -> 0.165 | W21: =(H21-O21)/1000 -> 0.03 | Y21: =SUM(Q21:T21) -> 2.831 | Z21: =V21+W21 -> 0.195 | AA21: =SUM(Q21:W21) -> 3.026
A22: 99996 | B22: 1977-10 | C22: 4968 | D22: 695 | E22: 241 | F22: 973 | G22: 786 | H22: 247 | J22: 1415 | K22: 174 | L22: 150 | M22: 752 | N22: 1069 | O22: 141 | Q22: =(C22-J22)/1000 -> 3.553 | R22: =(D22-K22)/1000 -> 0.521 | S22: =(E22-L22)/1000 -> 0.091 | T22: =(G22-N22)/1000 -> -0.283 | V22: =(F22-M22)/1000 -> 0.221 | W22: =(H22-O22)/1000 -> 0.106 | Y22: =SUM(Q22:T22) -> 3.882 | Z22: =V22+W22 -> 0.327 | AA22: =SUM(Q22:W22) -> 4.209 | AD22: =AD11 -> 12 m Net | AE22: =AE11 -> 12 m Net | AF22: =AF11 -> 12 m Net | AI22: 12 m Net | AJ22: 12 m Net | AK22: 12 m Net | AL22: 12 m Net | AM22: 12M Net non
A23: 99996 | B23: 1977-11 | C23: 4803 | D23: 626 | E23: 129 | F23: 1281 | G23: 593 | H23: 214 | J23: 1728 | K23: 120 | L23: 116 | M23: 899 | N23: 921 | O23: 180 | Q23: =(C23-J23)/1000 -> 3.075 | R23: =(D23-K23)/1000 -> 0.506 | S23: =(E23-L23)/1000 -> 0.013 | T23: =(G23-N23)/1000 -> -0.328 | V23: =(F23-M23)/1000 -> 0.382 | W23: =(H23-O23)/1000 -> 0.034 | Y23: =SUM(Q23:T23) -> 3.266 | Z23: =V23+W23 -> 0.416 | AA23: =SUM(Q23:W23) -> 3.682 | AD23: =AD12 -> Bond | AE23: =AE12 -> stk | AF23: =AF12 -> Net flows | AI23: Treasury | AJ23: Agency | AK23: Corp | AL23: For bonds | AM23: Treasury Flows
A24: 99996 | B24: 1977-12 | C24: 2330 | D24: 154 | E24: 179 | F24: 1235 | G24: 885 | H24: 291 | J24: 1467 | K24: 146 | L24: 159 | M24: 945 | N24: 1224 | O24: 232 | Q24: =(C24-J24)/1000 -> 0.863 | R24: =(D24-K24)/1000 -> 0.008 | S24: =(E24-L24)/1000 -> 0.02 | T24: =(G24-N24)/1000 -> -0.339 | V24: =(F24-M24)/1000 -> 0.29 | W24: =(H24-O24)/1000 -> 0.059 | Y24: =SUM(Q24:T24) -> 0.552 | Z24: =V24+W24 -> 0.349 | AA24: =SUM(Q24:W24) -> 0.901 | AC24: =B24 -> 1977-12 | AD24: =SUM(Y13:Y24) -> 22.814 | AE24: =SUM(Z13:Z24) -> 2.263 | AF24: =SUM(AA13:AA24) -> 25.077 | AH24: 28460 | AI24: =SUM(Q13:Q24) -> 23.6 | AJ24: =SUM(R13:R24) -> 2.76 | AK24: =SUM(S13:S24) -> 1.55 | AL24: =SUM(T13:T24) -> -5.096 | AM24: =AF24-AI24 -> 1.477
A25: 99996 | B25: 1978-01 | C25: 3380 | D25: 325 | E25: 134 | F25: 1024 | G25: 818 | H25: 255 | J25: 1899 | K25: 259 | L25: 119 | M25: 909 | N25: 1454 | O25: 152 | Q25: =(C25-J25)/1000 -> 1.481 | R25: =(D25-K25)/1000 -> 0.066 | S25: =(E25-L25)/1000 -> 0.015 | T25: =(G25-N25)/1000 -> -0.636 | V25: =(F25-M25)/1000 -> 0.115 | W25: =(H25-O25)/1000 -> 0.103 | Y25: =SUM(Q25:T25) -> 0.926 | Z25: =V25+W25 -> 0.218 | AA25: =SUM(Q25:W25) -> 1.144 | AC25: =B25 -> 1978-01 | AD25: =SUM(Y14:Y25) -> 23.229 | AE25: =SUM(Z14:Z25) -> 2.201 | AF25: =SUM(AA14:AA25) -> 25.43 | AH25: 28491 | AI25: =SUM(Q14:Q25) -> 24.571 | AJ25: =SUM(R14:R25) -> 2.738 | AK25: =SUM(S14:S25) -> 1.57 | AL25: =SUM(T14:T25) -> -5.65 | AM25: =AF25-AI25 -> 0.859
A26: 99996 | B26: 1978-02 | C26: 2360 | D26: 344 | E26: 230 | F26: 826 | G26: 597 | H26: 280 | J26: 2082 | K26: 249 | L26: 99 | M26: 762 | N26: 789 | O26: 167 | Q26: =(C26-J26)/1000 -> 0.278 | R26: =(D26-K26)/1000 -> 0.095 | S26: =(E26-L26)/1000 -> 0.131 | T26: =(G26-N26)/1000 -> -0.192 | V26: =(F26-M26)/1000 -> 0.064 | W26: =(H26-O26)/1000 -> 0.113 | Y26: =SUM(Q26:T26) -> 0.312 | Z26: =V26+W26 -> 0.177 | AA26: =SUM(Q26:W26) -> 0.489 | AC26: =B26 -> 1978-02 | AD26: =SUM(Y15:Y26) -> 22.314 | AE26: =SUM(Z15:Z26) -> 2.351 | AF26: =SUM(AA15:AA26) -> 24.665 | AH26: 28522 | AI26: =SUM(Q15:Q26) -> 23.553 | AJ26: =SUM(R15:R26) -> 2.828 | AK26: =SUM(S15:S26) -> 1.389 | AL26: =SUM(T15:T26) -> -5.456 | AM26: =AF26-AI26 -> 1.112
A27: 99996 | B27: 1978-03 | C27: 2627 | D27: 420 | E27: 183 | F27: 1414 | G27: 819 | H27: 337 | J27: 1756 | K27: 450 | L27: 201 | M27: 922 | N27: 1436 | O27: 223 | Q27: =(C27-J27)/1000 -> 0.871 | R27: =(D27-K27)/1000 -> -0.03 | S27: =(E27-L27)/1000 -> -0.018 | T27: =(G27-N27)/1000 -> -0.617 | V27: =(F27-M27)/1000 -> 0.492 | W27: =(H27-O27)/1000 -> 0.114 | Y27: =SUM(Q27:T27) -> 0.206 | Z27: =V27+W27 -> 0.606 | AA27: =SUM(Q27:W27) -> 0.812 | AC27: =B27 -> 1978-03 | AD27: =SUM(Y16:Y27) -> 20.98 | AE27: =SUM(Z16:Z27) -> 2.895 | AF27: =SUM(AA16:AA27) -> 23.875 | AH27: 28550 | AI27: =SUM(Q16:Q27) -> 22.919 | AJ27: =SUM(R16:R27) -> 2.722 | AK27: =SUM(S16:S27) -> 1.325 | AL27: =SUM(T16:T27) -> -5.986 | AM27: =AF27-AI27 -> 0.956
A28: 99996 | B28: 1978-04 | C28: 1798 | D28: 162 | E28: 149 | F28: 1864 | G28: 1237 | H28: 407 | J28: 3377 | K28: 160 | L28: 186 | M28: 1150 | N28: 1723 | O28: 262 | Q28: =(C28-J28)/1000 -> -1.579 | R28: =(D28-K28)/1000 -> 0.002 | S28: =(E28-L28)/1000 -> -0.037 | T28: =(G28-N28)/1000 -> -0.486 | V28: =(F28-M28)/1000 -> 0.714 | W28: =(H28-O28)/1000 -> 0.145 | Y28: =SUM(Q28:T28) -> -2.1 | Z28: =V28+W28 -> 0.859 | AA28: =SUM(Q28:W28) -> -1.241 | AC28: =B28 -> 1978-04 | AD28: =SUM(Y17:Y28) -> 17.369 | AE28: =SUM(Z17:Z28) -> 3.562 | AF28: =SUM(AA17:AA28) -> 20.931 | AH28: 28581 | AI28: =SUM(Q17:Q28) -> 20.395 | AJ28: =SUM(R17:R28) -> 2.404 | AK28: =SUM(S17:S28) -> 0.974 | AL28: =SUM(T17:T28) -> -6.404 | AM28: =AF28-AI28 -> 0.536
A29: 99996 | B29: 1978-05 | C29: 2982 | D29: 266 | E29: 514 | F29: 2394 | G29: 1020 | H29: 272 | J29: 3278 | K29: 171 | L29: 193 | M29: 1966 | N29: 1063 | O29: 284 | Q29: =(C29-J29)/1000 -> -0.296 | R29: =(D29-K29)/1000 -> 0.095 | S29: =(E29-L29)/1000 -> 0.321 | T29: =(G29-N29)/1000 -> -0.043 | V29: =(F29-M29)/1000 -> 0.428 | W29: =(H29-O29)/1000 -> -0.012 | Y29: =SUM(Q29:T29) -> 0.077 | Z29: =V29+W29 -> 0.416 | AA29: =SUM(Q29:W29) -> 0.493 | AC29: =B29 -> 1978-05 | AD29: =SUM(Y18:Y29) -> 17.112 | AE29: =SUM(Z18:Z29) -> 3.759 | AF29: =SUM(AA18:AA29) -> 20.871 | AH29: 28611 | AI29: =SUM(Q18:Q29) -> 19.211 | AJ29: =SUM(R18:R29) -> 2.38 | AK29: =SUM(S18:S29) -> 1.103 | AL29: =SUM(T18:T29) -> -5.582 | AM29: =AF29-AI29 -> 1.66
A30: 99996 | B30: 1978-06 | C30: 2965 | D30: 416 | E30: 255 | F30: 2094 | G30: 1110 | H30: 247 | J30: 1695 | K30: 188 | L30: 122 | M30: 1938 | N30: 1746 | O30: 308 | Q30: =(C30-J30)/1000 -> 1.27 | R30: =(D30-K30)/1000 -> 0.228 | S30: =(E30-L30)/1000 -> 0.133 | T30: =(G30-N30)/1000 -> -0.636 | V30: =(F30-M30)/1000 -> 0.156 | W30: =(H30-O30)/1000 -> -0.061 | Y30: =SUM(Q30:T30) -> 0.995 | Z30: =V30+W30 -> 0.095 | AA30: =SUM(Q30:W30) -> 1.09 | AC30: =B30 -> 1978-06 | AD30: =SUM(Y19:Y30) -> 15.961 | AE30: =SUM(Z19:Z30) -> 3.663 | AF30: =SUM(AA19:AA30) -> 19.624 | AH30: 28642 | AI30: =SUM(Q19:Q30) -> 18.155 | AJ30: =SUM(R19:R30) -> 2.143 | AK30: =SUM(S19:S30) -> 1.103 | AL30: =SUM(T19:T30) -> -5.44 | AM30: =AF30-AI30 -> 1.469
A31: 99996 | B31: 1978-07 | C31: 2663 | D31: 679 | E31: 371 | F31: 1306 | G31: 941 | H31: 333 | J31: 2173 | K31: 261 | L31: 370 | M31: 1297 | N31: 1284 | O31: 323 | Q31: =(C31-J31)/1000 -> 0.49 | R31: =(D31-K31)/1000 -> 0.418 | S31: =(E31-L31)/1000 -> 0.001 | T31: =(G31-N31)/1000 -> -0.343 | V31: =(F31-M31)/1000 -> 0.009 | W31: =(H31-O31)/1000 -> 0.01 | Y31: =SUM(Q31:T31) -> 0.566 | Z31: =V31+W31 -> 0.019 | AA31: =SUM(Q31:W31) -> 0.585 | AC31: =B31 -> 1978-07 | AD31: =SUM(Y20:Y31) -> 14.904 | AE31: =SUM(Z20:Z31) -> 3.737 | AF31: =SUM(AA20:AA31) -> 18.641 | AH31: 28672 | AI31: =SUM(Q20:Q31) -> 17.438 | AJ31: =SUM(R20:R31) -> 2.256 | AK31: =SUM(S20:S31) -> 0.789 | AL31: =SUM(T20:T31) -> -5.579 | AM31: =AF31-AI31 -> 1.203
A32: 99996 | B32: 1978-08 | C32: 2853 | D32: 398 | E32: 471 | F32: 2446 | G32: 990 | H32: 383 | J32: 2427 | K32: 266 | L32: 224 | M32: 2680 | N32: 1189 | O32: 331 | Q32: =(C32-J32)/1000 -> 0.426 | R32: =(D32-K32)/1000 -> 0.132 | S32: =(E32-L32)/1000 -> 0.247 | T32: =(G32-N32)/1000 -> -0.199 | V32: =(F32-M32)/1000 -> -0.234 | W32: =(H32-O32)/1000 -> 0.052 | Y32: =SUM(Q32:T32) -> 0.606 | Z32: =V32+W32 -> -0.182 | AA32: =SUM(Q32:W32) -> 0.424 | AC32: =B32 -> 1978-08 | AD32: =SUM(Y21:Y32) -> 12.119 | AE32: =SUM(Z21:Z32) -> 3.495 | AF32: =SUM(AA21:AA32) -> 15.614 | AH32: 28703 | AI32: =SUM(Q21:Q32) -> 13.868 | AJ32: =SUM(R21:R32) -> 2.051 | AK32: =SUM(S21:S32) -> 0.956 | AL32: =SUM(T21:T32) -> -4.756 | AM32: =AF32-AI32 -> 1.746
A33: 99996 | B33: 1978-09 | C33: 2516 | D33: 289 | E33: 321 | F33: 2357 | G33: 774 | H33: 261 | J33: 1877 | K33: 282 | L33: 268 | M33: 2115 | N33: 735 | O33: 330 | Q33: =(C33-J33)/1000 -> 0.639 | R33: =(D33-K33)/1000 -> 0.007 | S33: =(E33-L33)/1000 -> 0.053 | T33: =(G33-N33)/1000 -> 0.039 | V33: =(F33-M33)/1000 -> 0.242 | W33: =(H33-O33)/1000 -> -0.069 | Y33: =SUM(Q33:T33) -> 0.738 | Z33: =V33+W33 -> 0.173 | AA33: =SUM(Q33:W33) -> 0.911 | AC33: =B33 -> 1978-09 | AD33: =SUM(Y22:Y33) -> 10.026 | AE33: =SUM(Z22:Z33) -> 3.473 | AF33: =SUM(AA22:AA33) -> 13.499 | AH33: 28734 | AI33: =SUM(Q22:Q33) -> 11.071 | AJ33: =SUM(R22:R33) -> 2.048 | AK33: =SUM(S22:S33) -> 0.97 | AL33: =SUM(T22:T33) -> -4.063 | AM33: =AF33-AI33 -> 2.428
A34: 99996 | B34: 1978-10 | C34: 4219 | D34: 419 | E34: 309 | F34: 1521 | G34: 924 | H34: 299 | J34: 2809 | K34: 338 | L34: 192 | M34: 1523 | N34: 1612 | O34: 318 | Q34: =(C34-J34)/1000 -> 1.41 | R34: =(D34-K34)/1000 -> 0.081 | S34: =(E34-L34)/1000 -> 0.117 | T34: =(G34-N34)/1000 -> -0.688 | V34: =(F34-M34)/1000 -> -0.002 | W34: =(H34-O34)/1000 -> -0.019 | Y34: =SUM(Q34:T34) -> 0.92 | Z34: =V34+W34 -> -0.021 | AA34: =SUM(Q34:W34) -> 0.899 | AC34: =B34 -> 1978-10 | AD34: =SUM(Y23:Y34) -> 7.064 | AE34: =SUM(Z23:Z34) -> 3.125 | AF34: =SUM(AA23:AA34) -> 10.189 | AH34: 28764 | AI34: =SUM(Q23:Q34) -> 8.928 | AJ34: =SUM(R23:R34) -> 1.608 | AK34: =SUM(S23:S34) -> 0.996 | AL34: =SUM(T23:T34) -> -4.468 | AM34: =AF34-AI34 -> 1.261
A35: 99996 | B35: 1978-11 | C35: 2960 | D35: 220 | E35: 217 | F35: 1461 | G35: 856 | H35: 360 | J35: 2736 | K35: 184 | L35: 342 | M35: 1359 | N35: 1318 | O35: 197 | Q35: =(C35-J35)/1000 -> 0.224 | R35: =(D35-K35)/1000 -> 0.036 | S35: =(E35-L35)/1000 -> -0.125 | T35: =(G35-N35)/1000 -> -0.462 | V35: =(F35-M35)/1000 -> 0.102 | W35: =(H35-O35)/1000 -> 0.163 | Y35: =SUM(Q35:T35) -> -0.327 | Z35: =V35+W35 -> 0.265 | AA35: =SUM(Q35:W35) -> -0.062 | AC35: =B35 -> 1978-11 | AD35: =SUM(Y24:Y35) -> 3.471 | AE35: =SUM(Z24:Z35) -> 2.974 | AF35: =SUM(AA24:AA35) -> 6.445 | AH35: 28795 | AI35: =SUM(Q24:Q35) -> 6.077 | AJ35: =SUM(R24:R35) -> 1.138 | AK35: =SUM(S24:S35) -> 0.858 | AL35: =SUM(T24:T35) -> -4.602 | AM35: =AF35-AI35 -> 0.368
... A421: 99996 | B421: 2011-01 | C421: 1422938 | D421: 96479 | E421: 97409 | F421: 574912 | G421: 279141 | H421: 316010 | J421: 1376467 | K421: 85205 | L421: 96754 | M421: 558982 | N421: 283803 | O421: 334175 | Q421: =(C421-J421)/1000 -> 46.471 | R421: =(D421-K421)/1000 -> 11.274 | S421: =(E421-L421)/1000 -> 0.655 | T421: =(G421-N421)/1000 -> -4.662 | V421: =(F421-M421)/1000 -> 15.93 | W421: =(H421-O421)/1000 -> -18.165 | Y421: =SUM(Q421:T421) -> 53.738 | Z421: =V421+W421 -> -2.235 | AA421: =SUM(Q421:W421) -> 51.503 | AC421: =B421 -> 2011-01 | AD421: =SUM(Y410:Y421) -> 770.934 | AE421: =SUM(Z410:Z421) -> 47.348 | AF421: =SUM(AA410:AA421) -> 818.282 | AH421: 40544 | AI421: =SUM(Q410:Q421) -> 691.487 | AJ421: =SUM(R410:R421) -> 131.403 | AK421: =SUM(S410:S421) -> 20.971 | AL421: =SUM(T410:T421) -> -72.927 | AM421: =AF421-AI421 -> 126.795
A422: 99996 | B422: 2011-02 | C422: 1515097 | D422: 77070 | E422: 92950 | F422: 595067 | G422: 295445 | H422: 342644 | J422: 1485203 | K422: 78659 | L422: 95570 | M422: 588972 | N422: 287757 | O422: 355863 | Q422: =(C422-J422)/1000 -> 29.894 | R422: =(D422-K422)/1000 -> -1.589 | S422: =(E422-L422)/1000 -> -2.62 | T422: =(G422-N422)/1000 -> 7.688 | V422: =(F422-M422)/1000 -> 6.095 | W422: =(H422-O422)/1000 -> -13.219 | Y422: =SUM(Q422:T422) -> 33.373 | Z422: =V422+W422 -> -7.124 | AA422: =SUM(Q422:W422) -> 26.249 | AC422: 2011-02 | AD422: =SUM(Y411:Y422) -> 770.04 | AE422: =SUM(Z411:Z422) -> 28.664 | AF422: =SUM(AA411:AA422) -> 798.704 | AH422: 40575 | AI422: =SUM(Q411:Q422) -> 673.179 | AJ422: =SUM(R411:R422) -> 127.635 | AK422: =SUM(S411:S422) -> 30.441 | AL422: =SUM(T411:T422) -> -61.215 | AM422: =AF422-AI422 -> 125.525
A423: 99996 | B423: 2011-03 | C423: 1732864 | D423: 86287 | E423: 109584 | F423: 732444 | G423: 385367 | H423: 403391 | J423: 1706837 | K423: 76794 | L423: 106238 | M423: 717867 | N423: 402292 | O423: 417123 | Q423: =(C423-J423)/1000 -> 26.027 | R423: =(D423-K423)/1000 -> 9.493 | S423: =(E423-L423)/1000 -> 3.346 | T423: =(G423-N423)/1000 -> -16.925 | V423: =(F423-M423)/1000 -> 14.577 | W423: =(H423-O423)/1000 -> -13.732 | Y423: =SUM(Q423:T423) -> 21.941 | Z423: =V423+W423 -> 0.845 | AA423: =SUM(Q423:W423) -> 22.786 | AC423: 2011-03 | AD423: =SUM(Y412:Y423) -> 662.845 | AE423: =SUM(Z412:Z423) -> 20.24 | AF423: =SUM(AA412:AA423) -> 683.085 | AH423: 40603 | AI423: =SUM(Q412:Q423) -> 591.558 | AJ423: =SUM(R412:R423) -> 116.546 | AK423: =SUM(S412:S423) -> 17.802 | AL423: =SUM(T412:T423) -> -63.061 | AM423: =AF423-AI423 -> 91.527
A424: 99996 | B424: 2011-04 | C424: 1267441 | D424: 86587 | E424: 84436 | F424: 593135 | G424: 316165 | H424: 328232 | J424: 1243831 | K424: 79083 | L424: 89306 | M424: 575330 | N424: 317484 | O424: 341226 | Q424: =(C424-J424)/1000 -> 23.61 | R424: =(D424-K424)/1000 -> 7.504 | S424: =(E424-L424)/1000 -> -4.87 | T424: =(G424-N424)/1000 -> -1.319 | V424: =(F424-M424)/1000 -> 17.805 | W424: =(H424-O424)/1000 -> -12.994 | Y424: =SUM(Q424:T424) -> 24.925 | Z424: =V424+W424 -> 4.811 | AA424: =SUM(Q424:W424) -> 29.736 | AC424: 2011-04 | AD424: =SUM(Y413:Y424) -> 608.869 | AE424: =SUM(Z413:Z424) -> 28.609 | AF424: =SUM(AA413:AA424) -> 637.478 | AH424: 40634 | AI424: =SUM(Q413:Q424) -> 537.977 | AJ424: =SUM(R413:R424) -> 113.798 | AK424: =SUM(S413:S424) -> 2.942 | AL424: =SUM(T413:T424) -> -45.848 | AM424: =AF424-AI424 -> 99.501
A425: 99996 | B425: 2011-05 | C425: 1634416 | D425: 75232 | E425: 87647 | F425: 673811 | G425: 316006 | H425: 341585 | J425: 1598091 | K425: 83548 | L425: 82088 | M425: 664589 | N425: 330075 | O425: 347912 | Q425: =(C425-J425)/1000 -> 36.325 | R425: =(D425-K425)/1000 -> -8.316 | S425: =(E425-L425)/1000 -> 5.559 | T425: =(G425-N425)/1000 -> -14.069 | V425: =(F425-M425)/1000 -> 9.222 | W425: =(H425-O425)/1000 -> -6.327 | Y425: =SUM(Q425:T425) -> 19.499 | Z425: =V425+W425 -> 2.895 | AA425: =SUM(Q425:W425) -> 22.394 | AC425: 2011-05 | AD425: =SUM(Y414:Y425) -> 587.536 | AE425: =SUM(Z414:Z425) -> 41.479 | AF425: =SUM(AA414:AA425) -> 629.015 | AH425: 40664 | AI425: =SUM(Q414:Q425) -> 559.185 | AJ425: =SUM(R414:R425) -> 83.112 | AK425: =SUM(S414:S425) -> 17.656 | AL425: =SUM(T414:T425) -> -72.417 | AM425: =AF425-AI425 -> 69.83
A426: 99996 | B426: 2011-06 | C426: 1708114 | D426: 82582 | E426: 114251 | F426: 665514 | G426: 360013 | H426: 341182 | J426: 1711786 | K426: 82836 | L426: 125031 | M426: 661721 | N426: 346613 | O426: 339524 | Q426: =(C426-J426)/1000 -> -3.672 | R426: =(D426-K426)/1000 -> -0.254 | S426: =(E426-L426)/1000 -> -10.78 | T426: =(G426-N426)/1000 -> 13.4 | V426: =(F426-M426)/1000 -> 3.793 | W426: =(H426-O426)/1000 -> 1.658 | Y426: =SUM(Q426:T426) -> -1.306 | Z426: =V426+W426 -> 5.451 | AA426: =SUM(Q426:W426) -> 4.145 | AC426: 2011-06 | AD426: =SUM(Y415:Y426) -> 545.957 | AE426: =SUM(Z415:Z426) -> 47.06 | AF426: =SUM(AA415:AA426) -> 593.017 | AH426: 40695 | AI426: =SUM(Q415:Q426) -> 523.785 | AJ426: =SUM(R415:R426) -> 66.059 | AK426: =SUM(S415:S426) -> 20.774 | AL426: =SUM(T415:T426) -> -64.661 | AM426: =AF426-AI426 -> 69.232
...

Sheet Basic Balance
B1: TWI | C1: Ln(TWI) | F1: TB (Bloomberg) | G1: TB 12 M Sum | J1: Trade Balance | K1: Net non-treasury portfolio flows | L1: Basic Balance
A2: 1993-01 | B2: 87.662392 | C2: =LN(B2) -> 4.473493 | E2: =A2 -> 1993-01
A3: 1993-02 | B3: 87.948698 | C3: =LN(B3) -> 4.4767537 | E3: =A3 -> 1993-02
A4: 1993-03 | B4: 87.26198 | C4: =LN(B4) -> 4.4689149 | E4: =A4 -> 1993-03
A5: 1993-04 | B5: 85.328682 | C5: =LN(B5) -> 4.4465106 | E5: =A5 -> 1993-04
A6: 1993-05 | B6: 85.052434 | C6: =LN(B6) -> 4.4432679 | E6: =A6 -> 1993-05
A7: 1993-06 | B7: 85.639649 | C7: =LN(B7) -> 4.4501484 | E7: =A7 -> 1993-06 | F7: -6.929
A8: 1993-07 | B8: 87.574974 | C8: =LN(B8) -> 4.4724953 | E8: =A8 -> 1993-07 | F8: -6.382
A9: 1993-08 | B9: 87.870217 | C9: =LN(B9) -> 4.4758609 | E9: =A9 -> 1993-08 | F9: -5.581
A10: 1993-09 | B10: 86.007472 | C10: =LN(B10) -> 4.4544342 | E10: =A10 -> 1993-09 | F10: -7.031
A11: 1993-10 | B11: 87.075804 | C11: =LN(B11) -> 4.466779 | E11: =A11 -> 1993-10 | F11: -6.594
A12: 1993-11 | B12: 88.335492 | C12: =LN(B12) -> 4.481142 | E12: =A12 -> 1993-11 | F12: -7.016
A13: 1993-12 | B13: 89.112308 | C13: =LN(B13) -> 4.4898975 | E13: =A13 -> 1993-12 | F13: -5.719
A14: 1994-01 | B14: 89.488551 | C14: =LN(B14) -> 4.4941107 | E14: =A14 -> 1994-01 | F14: -6.207
A15: 1994-02 | B15: 88.851149 | C15: =LN(B15) -> 4.4869625 | E15: =A15 -> 1994-02 | F15: -9.245
A16: 1994-03 | B16: 88.605019 | C16: =LN(B16) -> 4.4841885 | E16: =A16 -> 1994-03 | F16: -6.466
A17: 1994-04 | B17: 88.894084 | C17: =LN(B17) -> 4.4874456 | E17: =A17 -> 1994-04 | F17: -7.887
A18: 1994-05 | B18: 88.070503 | C18: =LN(B18) -> 4.4781377 | E18: =A18 -> 1994-05 | F18: -7.728 | G18: =SUM(F7:F18) -> -82.785 | I18: 34455 | J18: =G18 -> -82.785 | K18: ='TIC data'!AM221 -> -34.052 | L18: =G18+K18 -> -116.837
A19: 1994-06 | B19: 87.219607 | C19: =LN(B19) -> 4.4684292 | E19: =A19 -> 1994-06 | F19: -8.38 | G19: =SUM(F8:F19) -> -84.236 | I19: 34486 | J19: =G19 -> -84.236 | K19: ='TIC data'!AM222 -> -23.058 | L19: =G19+K19 -> -107.294
A20: 1994-07 | B20: 85.186222 | C20: =LN(B20) -> 4.4448397 | E20: =A20 -> 1994-07 | F20: -8.739 | G20: =SUM(F9:F20) -> -86.593 | I20: 34516 | J20: =G20 -> -86.593 | K20: ='TIC data'!AM223 -> -7.341 | L20: =G20+K20 -> -93.934
A21: 1994-08 | B21: 85.416171 | C21: =LN(B21) -> 4.4475354 | E21: =A21 -> 1994-08 | F21: -8.303 | G21: =SUM(F10:F21) -> -89.315 | I21: 34547 | J21: =G21 -> -89.315 | K21: ='TIC data'!AM224 -> 4.887 | L21: =G21+K21 -> -84.428
A22: 1994-09 | B22: 84.394202 | C22: =LN(B22) -> 4.4354987 | E22: =A22 -> 1994-09 | F22: -8.31 | G22: =SUM(F11:F22) -> -90.594 | I22: 34578 | J22: =G22 -> -90.594 | K22: ='TIC data'!AM225 -> 13.684 | L22: =G22+K22 -> -76.91
A23: 1994-10 | B23: 83.549117 | C23: =LN(B23) -> 4.4254347 | E23: =A23 -> 1994-10 | F23: -9.158 | G23: =SUM(F12:F23) -> -93.158 | I23: 34608 | J23: =G23 -> -93.158 | K23: ='TIC data'!AM226 -> 5.486 | L23: =G23+K23 -> -87.672
A24: 1994-11 | B24: 84.429999 | C24: =LN(B24) -> 4.4359228 | E24: =A24 -> 1994-11 | F24: -9.615 | G24: =SUM(F13:F24) -> -95.757 | I24: 34639 | J24: =G24 -> -95.757 | K24: ='TIC data'!AM227 -> 2.456 | L24: =G24+K24 -> -93.301
A25: 1994-12 | B25: 85.969922 | C25: =LN(B25) -> 4.4539975 | E25: =A25 -> 1994-12 | F25: -8.456 | G25: =SUM(F14:F25) -> -98.494 | I25: 34669 | J25: =G25 -> -98.494 | K25: ='TIC data'!AM228 -> 4.254 | L25: =G25+K25 -> -94.24
A26: 1995-01 | B26: 85.622733 | C26: =LN(B26) -> 4.4499508 | E26: =A26 -> 1995-01 | F26: -9.324 | G26: =SUM(F15:F26) -> -101.611 | I26: 34700 | J26: =G26 -> -101.611 | K26: ='TIC data'!AM229 -> 13.226 | L26: =G26+K26 -> -88.385
A27: 1995-02 | B27: 84.722708 | C27: =LN(B27) -> 4.4393837 | E27: =A27 -> 1995-02 | F27: -8.817 | G27: =SUM(F16:F27) -> -101.183 | I27: 34731 | J27: =G27 -> -101.183 | K27: ='TIC data'!AM230 -> 18.899 | L27: =G27+K27 -> -82.284
A28: 1995-03 | B28: 81.970608 | C28: =LN(B28) -> 4.4063607 | E28: =A28 -> 1995-03 | F28: -9.708 | G28: =SUM(F17:F28) -> -104.425 | I28: 34759 | J28: =G28 -> -104.425 | K28: ='TIC data'!AM231 -> 10.776 | L28: =G28+K28 -> -93.649
A29: 1995-04 | B29: 80.011424 | C29: =LN(B29) -> 4.3821694 | E29: =A29 -> 1995-04 | F29: -9.609 | G29: =SUM(F18:F29) -> -106.147 | I29: 34790 | J29: =G29 -> -106.147 | K29: ='TIC data'!AM232 -> 18.433 | L29: =G29+K29 -> -87.714
... A181: 2007-12 | B181: 73.1274 | C181: =LN(B181) -> 4.2922031 | E181: =A181 -> 2007-12 | F181: -58.759 | G181: =SUM(F170:F181) -> -707.222 | I181: 39417 | J181: =G181 -> -707.222 | K181: ='TIC data'!AM384 -> 581.442 | L181: =G181+K181 -> -125.78
A182: 2008-01 | B182: 72.6028 | C182: =LN(B182) -> 4.2850035 | E182: 2008-01 | F182: -61.486 | G182: =SUM(F171:F182) -> -711.698 | I182: 39448 | J182: =G182 -> -711.698 | K182: ='TIC data'!AM385 -> 501.694 | L182: =G182+K182 -> -210.004
A183: 2008-02 | B183: 72.2264 | C183: =LN(B183) -> 4.2798056 | E183: 2008-02 | F183: -61.749 | G183: =SUM(F172:F183) -> -715.565 | I183: 39479 | J183: =G183 -> -715.565 | K183: ='TIC data'!AM386 -> 493.429 | L183: =G183+K183 -> -222.136
A184: 2008-03 | B184: 70.0413 | C184: =LN(B184) -> 4.2490851 | E184: 2008-03 | F184: -59.42 | G184: =SUM(F173:F184) -> -712.297 | I184: 39508 | J184: =G184 -> -712.297 | K184: ='TIC data'!AM387 -> 485.112 | L184: =G184+K184 -> -227.185
A185: 2008-04 | B185: 70.291 | C185: =LN(B185) -> 4.2526438 | E185: 2008-04 | F185: -62.141 | G185: =SUM(F174:F185) -> -715.794 | I185: 39539 | J185: =G185 -> -715.794 | K185: ='TIC data'!AM388 -> 436.792 | L185: =G185+K185 -> -279.002
A186: 2008-05 | B186: 70.5716 | C186: =LN(B186) -> 4.2566278 | E186: 2008-05 | F186: -60.528 | G186: =SUM(F175:F186) -> -716.708 | I186: 39569 | J186: =G186 -> -716.708 | K186: ='TIC data'!AM389 -> 396.759 | L186: =G186+K186 -> -319.949
A187: 2008-06 | B187: 71.2117 | C187: =LN(B187) -> 4.2656571 | E187: 2008-06 | F187: -60.177 | G187: =SUM(F176:F187) -> -717.457 | I187: 39600 | J187: =G187 -> -717.457 | K187: ='TIC data'!AM390 -> 333.479 | L187: =G187+K187 -> -383.978
A188: 2008-07 | B188: 70.7745 | C188: =LN(B188) -> 4.2594988 | E188: 2008-07 | F188: -64.891 | G188: =SUM(F177:F188) -> -723.349 | I188: 39630 | J188: =G188 -> -723.349 | K188: ='TIC data'!AM391 -> 293.359 | L188: =G188+K188 -> -429.99
A189: 2008-08 | B189: 73.589 | C189: =LN(B189) -> 4.2984956 | E189: 2008-08 | F189: -60.913 | G189: =SUM(F178:F189) -> -727.458 | I189: 39661 | J189: =G189 -> -727.458 | K189: ='TIC data'!AM392 -> 343 | L189: =G189+K189 -> -384.458
A190: 2008-09 | B190: 74.744 | C190: =LN(B190) -> 4.3140689 | E190: 2008-09 | F190: -60.14 | G190: =SUM(F179:F190) -> -731.145 | I190: 39692 | J190: =G190 -> -731.145 | K190: ='TIC data'!AM393 -> 392.823 | L190: =G190+K190 -> -338.322
A191: 2008-10 | B191: 78.8054 | C191: =LN(B191) -> 4.3669815 | E191: 2008-10 | F191: -59.389 | G191: =SUM(F180:F191) -> -732.711 | I191: 39722 | J191: =G191 -> -732.711 | K191: ='TIC data'!AM394 -> 286.723 | L191: =G191+K191 -> -445.988
...

Sheet Disclaimer
